Workbook

Sheet time
C3: Warmup | E3: Retrieve
C4: Start | D4: End | E4: Start | F4: End
B5: Random 20 | C5: 0.40708333 | D5: 0.41607639 | E5: 0.41666667 | F5: 0.42696759
B6: PT 20 | C6: 0.43207176 | D6: 0.44114583 | E6: 0.41666667 | F6: 0.4506713
B7: Random 40 | C7: 0.53680556 | D7: 0.54590278 | E7: 0.54652778 | F7: 0.55560185
B8: PT 40 | C8: 0.57152778 | D8: 0.58153935 | E8: 0.58263889 | F8: 0.59162037
B9: Random 60 | C9: 0.08818287 | D9: 0.099270833 | E9: 0.099293981 | F9: 0.10880787
B10: PT 60 | C10: 0.21525463 | D10: 0.22773148 | E10: 0.22847222 | F10: 0.2387963
B11: Random 80 | C11: 0.28888889 | D11: 0.30997685 | E11: 0.30763889 | F11: 0.32159722
B12: PT 80 | C12: 0.33097222 | D12: 0.34190972 | E12: 0.34219907 | F12: 0.35224537
B13: Random 100 | C13: 0.37291667 | D13: 0.38289352 | E13: 0.38333333 | F13: 0.39230324
B14: PT 100 | C14: 0.40303241 | D14: 0.41273148 | E14: 0.41319444

Sheet info
B1: 59001
B2: 01 | C2: c5-4xlarge | D2: ="c"&B2&"-"&C2 -> c01-c5-4xlarge | E2: 172.31.16.10 | F2: 0 0 0 | H2: c01-c5-4xlarge
B3: 02 | C3: t2-small | D3: ="c"&B3&"-"&C3 -> c02-t2-small | E3: 172.31.27.28 | F3: c01-c5-4xlarge 172.31.16.10 59001 | H3: c02-t2-small
B4: 03 | C4: t2-small | D4: ="c"&B4&"-"&C4 -> c03-t2-small | E4: 172.31.24.48 | F4: c01-c5-4xlarge 172.31.16.10 59001 | H4: c03-t2-small
A5: ` | B5: 04 | C5: t2-small | D5: ="c"&B5&"-"&C5 -> c04-t2-small | E5: 172.31.19.20 | F5: c01-c5-4xlarge 172.31.16.10 59001 | H5: c04-t2-small
B6: 05 | C6: t2-medium | D6: ="c"&B6&"-"&C6 -> c05-t2-medium | E6: 172.31.21.44 | F6: c01-c5-4xlarge 172.31.16.10 59001 | H6: c05-t2-medium
B7: 06 | C7: t2-medium | D7: ="c"&B7&"-"&C7 -> c06-t2-medium | E7: 172.31.42.48 | F7: c01-c5-4xlarge 172.31.16.10 59001 | H7: c06-t2-medium
B8: 07 | C8: t2-medium | D8: ="c"&B8&"-"&C8 -> c07-t2-medium | E8: 172.31.6.148 | F8: c01-c5-4xlarge 172.31.16.10 59001 | H8: c07-t2-medium
B9: 08 | C9: c5-xlarge | D9: ="c"&B9&"-"&C9 -> c08-c5-xlarge | E9: 172.31.21.20 | F9: c01-c5-4xlarge 172.31.16.10 59001 | H9: c08-c5-xlarge
B10: 09 | C10: c5-xlarge | D10: ="c"&B10&"-"&C10 -> c09-c5-xlarge | E10: 172.31.29.51 | F10: c01-c5-4xlarge 172.31.16.10 59001 | H10: c09-c5-xlarge
B11: 10 | C11: c5-2xlarge | D11: ="c"&B11&"-"&C11 -> c10-c5-2xlarge | E11: 172.31.27.113 | F11: c01-c5-4xlarge 172.31.16.10 59001 | H11: c10-c5-2xlarge
B12: 11 | C12: c5-4xlarge | D12: ="c"&B12&"-"&C12 -> c11-c5-4xlarge | E12: 172.31.31.235 | F12: c01-c5-4xlarge 172.31.16.10 59001 | H12: c11-c5-4xlarge
B13: 12 | C13: t2-small | D13: ="c"&B13&"-"&C13 -> c12-t2-small | E13: 172.31.23.24 | F13: c11-c5-4xlarge 172.31.21.44 59001 | H13: c12-t2-small
B14: 13 | C14: t2-small | D14: ="c"&B14&"-"&C14 -> c13-t2-small | E14: 172.31.28.220 | F14: c11-c5-4xlarge 172.31.21.44 59001 | H14: c13-t2-small
B15: 14 | C15: t2-small | D15: ="c"&B15&"-"&C15 -> c14-t2-small | E15: 172.31.28.38 | F15: c11-c5-4xlarge 172.31.21.44 59001 | H15: c14-t2-small
B16: 15 | C16: t2-medium | D16: ="c"&B16&"-"&C16 -> c15-t2-medium | E16: 172.31.31.7 | F16: c11-c5-4xlarge 172.31.21.44 59001 | H16: c15-t2-medium
B17: 16 | C17: t2-medium | D17: ="c"&B17&"-"&C17 -> c16-t2-medium | E17: 172.31.19.38 | F17: c11-c5-4xlarge 172.31.21.44 59001 | H17: c16-t2-medium
B18: 17 | C18: t2-medium | D18: ="c"&B18&"-"&C18 -> c17-t2-medium | E18: 172.31.19.160 | F18: c11-c5-4xlarge 172.31.21.44 59001 | H18: c17-t2-medium
B19: 18 | C19: c5-xlarge | D19: ="c"&B19&"-"&C19 -> c18-c5-xlarge | E19: 172.31.16.91 | F19: c11-c5-4xlarge 172.31.21.44 59001 | H19: c18-c5-xlarge
B20: 19 | C20: c5-xlarge | D20: ="c"&B20&"-"&C20 -> c19-c5-xlarge | E20: 172.31.22.207 | F20: c11-c5-4xlarge 172.31.21.44 59001 | H20: c19-c5-xlarge
B21: 20 | C21: c5-2xlarge | D21: ="c"&B21&"-"&C21 -> c20-c5-2xlarge | E21: 172.31.25.39 | F21: c11-c5-4xlarge 172.31.21.44 59001 | H21: c20-c5-2xlarge
B23: 21 | C23: c5-4xlarge | D23: ="c"&B23&"-"&C23 -> c21-c5-4xlarge | E23: 172.31.18.213 | F23: c11-c5-4xlarge 172.31.21.44 59001 | H23: c21-c5-4xlarge
... B105: 100 | C105: c5-2xlarge | D105: ="c"&B105&"-"&C105 -> c100-c5-2xlarge | E105: 172.31.28.55 | F105: c91-c5-4xlarge 172.31.22.253 59001 | H105: c100-c5-2xlarge

Sheet nodes
B3: =info!D2&","&info!E2&",59001" -> c01-c5-4xlarge,172.31.16.10,59001
B4: =info!D3&","&info!E3&",59001" -> c02-t2-small,172.31.27.28,59001
B5: =info!D4&","&info!E4&",59001" -> c03-t2-small,172.31.24.48,59001
B6: =info!D5&","&info!E5&",59001" -> c04-t2-small,172.31.19.20,59001
B7: =info!D6&","&info!E6&",59001" -> c05-t2-medium,172.31.21.44,59001
B8: =info!D7&","&info!E7&",59001" -> c06-t2-medium,172.31.42.48,59001
B9: =info!D8&","&info!E8&",59001" -> c07-t2-medium,172.31.6.148,59001
B10: =info!D9&","&info!E9&",59001" -> c08-c5-xlarge,172.31.21.20,59001
B11: =info!D10&","&info!E10&",59001" -> c09-c5-xlarge,172.31.29.51,59001
B12: =info!D11&","&info!E11&",59001" -> c10-c5-2xlarge,172.31.27.113,59001
B13: =info!D12&","&info!E12&",59001" -> c11-c5-4xlarge,172.31.31.235,59001
B14: =info!D13&","&info!E13&",59001" -> c12-t2-small,172.31.23.24,59001
... B22: =info!D21&","&info!E21&",59001" -> c20-c5-2xlarge,172.31.25.39,59001
B23: =info!D23&","&info!E23&",59001" -> c21-c5-4xlarge,172.31.18.213,59001
B24: =info!D24&","&info!E24&",59001" -> c22-t2-small,172.31.23.72,59001
B25: =info!D25&","&info!E25&",59001" -> c23-t2-small,172.31.31.24,59001
B26: =info!D26&","&info!E26&",59001" -> c24-t2-small,172.31.27.58,59001
B27: =info!D27&","&info!E27&",59001" -> c25-t2-medium,172.31.17.169,59001
B28: =info!D28&","&info!E28&",59001" -> c26-t2-medium,172.31.28.12,59001
B29: =info!D29&","&info!E29&",59001" -> c27-t2-medium,172.31.20.85,59001
B30: =info!D30&","&info!E30&",59001" -> c28-c5-xlarge,172.31.24.7,59001
B31: =info!D31&","&info!E31&",59001" -> c29-c5-xlarge,172.31.29.177,59001
B32: =info!D32&","&info!E32&",59001" -> c30-c5-2xlarge,172.31.18.111,59001
B33: =info!D33&","&info!E33&",59001" -> c31-c5-4xlarge,172.31.18.88,59001
B34: =info!D34&","&info!E34&",59001" -> c32-t2-small,172.31.27.94,59001
... B42: =info!D42&","&info!E42&",59001" -> c40-c5-2xlarge,172.31.23.103,59001
B43: =info!D44&","&info!E44&",59001" -> c41-c5-4xlarge,172.31.29.34,59001
B44: =info!D45&","&info!E45&",59001" -> c42-t2-small,172.31.31.208,59001
B45: =info!D46&","&info!E46&",59001" -> c43-t2-small,172.31.19.51,59001
B46: =info!D47&","&info!E47&",59001" -> c44-t2-small,172.31.31.54,59001
B47: =info!D48&","&info!E48&",59001" -> c45-t2-medium,172.31.26.164,59001
B48: =info!D49&","&info!E49&",59001" -> c46-t2-medium,172.31.25.233,59001
B49: =info!D50&","&info!E50&",59001" -> c47-t2-medium,172.31.22.203,59001
B50: =info!D51&","&info!E51&",59001" -> c48-c5-xlarge,172.31.19.225,59001
B51: =info!D52&","&info!E52&",59001" -> c49-c5-xlarge,172.31.26.244,59001
B52: =info!D53&","&info!E53&",59001" -> c50-c5-2xlarge,172.31.30.61,59001
B53: =info!D54&","&info!E54&",59001" -> c51-c5-4xlarge,172.31.29.11,59001
B54: =info!D55&","&info!E55&",59001" -> c52-t2-small,172.31.17.199,59001
... B62: =info!D63&","&info!E63&",59001" -> c60-c5-2xlarge,172.31.20.108,59001
B63: =info!D65&","&info!E65&",59001" -> c61-c5-4xlarge,172.31.27.188,59001
...

Sheet startServerRandom
B2: ssh -i p2pstorage.pem ec2-user@
B3: sh -c
B4: cd node; nohup ./startServer.sh
B5: > /dev/null 2>&1 &
B6: 59001
B7: 0 | C7: 2
B9: =B$2&info!E2&" "&CHAR(34)&B$3&CHAR(39)&B$4&" 2 1 "&info!D2&" "&info!E2&" "&B$6&" "&B$7&" "&C$7&" "&info!F2&B$5&CHAR(39)&CHAR(34) -> ssh -i p2pstorage.pem ec2-user@172.31.16.10 "sh -c 'cd node; nohup ./startServer.sh 2 1 c01-c5-4xlarge 172.31.16.10 59001 0 2 0 0 0 > /dev/null 2>&1 &'"
B10: sleep 10
B11: =B$2&info!E3&" "&CHAR(34)&B$3&CHAR(39)&B$4&" 2 2 "&info!D3&" "&info!E3&" "&B$6&" "&B$7&" "&C$7&" "&info!F3&B$5&CHAR(39)&CHAR(34) -> ssh -i p2pstorage.pem ec2-user@172.31.27.28 "sh -c 'cd node; nohup ./startServer.sh 2 2 c02-t2-small 172.31.27.28 59001 0 2 c01-c5-4xlarge 172.31.16.10 59001 > /dev/null 2>&1 &'"
B12: =B$2&info!E4&" "&CHAR(34)&B$3&CHAR(39)&B$4&" 2 2 "&info!D4&" "&info!E4&" "&B$6&" "&B$7&" "&C$7&" "&info!F4&B$5&CHAR(39)&CHAR(34) -> ssh -i p2pstorage.pem ec2-user@172.31.24.48 "sh -c 'cd node; nohup ./startServer.sh 2 2 c03-t2-small 172.31.24.48 59001 0 2 c01-c5-4xlarge 172.31.16.10 59001 > /dev/null 2>&1 &'"
B13: =B$2&info!E5&" "&CHAR(34)&B$3&CHAR(39)&B$4&" 2 2 "&info!D5&" "&info!E5&" "&B$6&" "&B$7&" "&C$7&" "&info!F5&B$5&CHAR(39)&CHAR(34) -> ssh -i p2pstorage.pem ec2-user@172.31.19.20 "sh -c 'cd node; nohup ./startServer.sh 2 2 c04-t2-small 172.31.19.20 59001 0 2 c01-c5-4xlarge 172.31.16.10 59001 > /dev/null 2>&1 &'"
B14: =B$2&info!E6&" "&CHAR(34)&B$3&CHAR(39)&B$4&" 2 2 "&info!D6&" "&info!E6&" "&B$6&" "&B$7&" "&C$7&" "&info!F6&B$5&CHAR(39)&CHAR(34) -> ssh -i p2pstorage.pem ec2-user@172.31.21.44 "sh -c 'cd node; nohup ./startServer.sh 2 2 c05-t2-medium 172.31.21.44 59001 0 2 c01-c5-4xlarge 172.31.16.10 59001 > /dev/null 2>&1 &'"
B15: =B$2&info!E7&" "&CHAR(34)&B$3&CHAR(39)&B$4&" 2 2 "&info!D7&" "&info!E7&" "&B$6&" "&B$7&" "&C$7&" "&info!F7&B$5&CHAR(39)&CHAR(34) -> ssh -i p2pstorage.pem ec2-user@172.31.42.48 "sh -c 'cd node; nohup ./startServer.sh 2 2 c06-t2-medium 172.31.42.48 59001 0 2 c01-c5-4xlarge 172.31.16.10 59001 > /dev/null 2>&1 &'"
B16: =B$2&info!E8&" "&CHAR(34)&B$3&CHAR(39)&B$4&" 2 2 "&info!D8&" "&info!E8&" "&B$6&" "&B$7&" "&C$7&" "&info!F8&B$5&CHAR(39)&CHAR(34) -> ssh -i p2pstorage.pem ec2-user@172.31.6.148 "sh -c 'cd node; nohup ./startServer.sh 2 2 c07-t2-medium 172.31.6.148 59001 0 2 c01-c5-4xlarge 172.31.16.10 59001 > /dev/null 2>&1 &'"
B17: =B$2&info!E9&" "&CHAR(34)&B$3&CHAR(39)&B$4&" 2 2 "&info!D9&" "&info!E9&" "&B$6&" "&B$7&" "&C$7&" "&info!F9&B$5&CHAR(39)&CHAR(34) -> ssh -i p2pstorage.pem ec2-user@172.31.21.20 "sh -c 'cd node; nohup ./startServer.sh 2 2 c08-c5-xlarge 172.31.21.20 59001 0 2 c01-c5-4xlarge 172.31.16.10 59001 > /dev/null 2>&1 &'"
B18: =B$2&info!E10&" "&CHAR(34)&B$3&CHAR(39)&B$4&" 2 2 "&info!D10&" "&info!E10&" "&B$6&" "&B$7&" "&C$7&" "&info!F10&B$5&CHAR(39)&CHAR(34) -> ssh -i p2pstorage.pem ec2-user@172.31.29.51 "sh -c 'cd node; nohup ./startServer.sh 2 2 c09-c5-xlarge 172.31.29.51 59001 0 2 c01-c5-4xlarge 172.31.16.10 59001 > /dev/null 2>&1 &'"
B19: =B$2&info!E11&" "&CHAR(34)&B$3&CHAR(39)&B$4&" 2 2 "&info!D11&" "&info!E11&" "&B$6&" "&B$7&" "&C$7&" "&info!F11&B$5&CHAR(39)&CHAR(34) -> ssh -i p2pstorage.pem ec2-user@172.31.27.113 "sh -c 'cd node; nohup ./startServer.sh 2 2 c10-c5-2xlarge 172.31.27.113 59001 0 2 c01-c5-4xlarge 172.31.16.10 59001 > /dev/null 2>&1 &'"
B20: =B$2&info!E12&" "&CHAR(34)&B$3&CHAR(39)&B$4&" 2 2 "&info!D12&" "&info!E12&" "&B$6&" "&B$7&" "&C$7&" "&info!F12&B$5&CHAR(39)&CHAR(34) -> ssh -i p2pstorage.pem ec2-user@172.31.31.235 "sh -c 'cd node; nohup ./startServer.sh 2 2 c11-c5-4xlarge 172.31.31.235 59001 0 2 c01-c5-4xlarge 172.31.16.10 59001 > /dev/null 2>&1 &'"
B21: =B$2&info!E13&" "&CHAR(34)&B$3&CHAR(39)&B$4&" 2 2 "&info!D13&" "&info!E13&" "&B$6&" "&B$7&" "&C$7&" "&info!F13&B$5&CHAR(39)&CHAR(34) -> ssh -i p2pstorage.pem ec2-user@172.31.23.24 "sh -c 'cd node; nohup ./startServer.sh 2 2 c12-t2-small 172.31.23.24 59001 0 2 c11-c5-4xlarge 172.31.21.44 59001 > /dev/null 2>&1 &'"
B22: =B$2&info!E14&" "&CHAR(34)&B$3&CHAR(39)&B$4&" 2 2 "&info!D14&" "&info!E14&" "&B$6&" "&B$7&" "&C$7&" "&info!F14&B$5&CHAR(39)&CHAR(34) -> ssh -i p2pstorage.pem ec2-user@172.31.28.220 "sh -c 'cd node; nohup ./startServer.sh 2 2 c13-t2-small 172.31.28.220 59001 0 2 c11-c5-4xlarge 172.31.21.44 59001 > /dev/null 2>&1 &'"
... B29: =B$2&info!E21&" "&CHAR(34)&B$3&CHAR(39)&B$4&" 2 2 "&info!D21&" "&info!E21&" "&B$6&" "&B$7&" "&C$7&" "&info!F21&B$5&CHAR(39)&CHAR(34) -> ssh -i p2pstorage.pem ec2-user@172.31.25.39 "sh -c 'cd node; nohup ./startServer.sh 2 2 c20-c5-2xlarge 172.31.25.39 59001 0 2 c11-c5-4xlarge 172.31.21.44 59001 > /dev/null 2>&1 &'"
B30: sleep 30
B31: =B$2&info!E23&" "&CHAR(34)&B$3&CHAR(39)&B$4&" 2 2 "&info!D23&" "&info!E23&" "&B$6&" "&B$7&" "&C$7&" "&info!F23&B$5&CHAR(39)&CHAR(34) -> ssh -i p2pstorage.pem ec2-user@172.31.18.213 "sh -c 'cd node; nohup ./startServer.sh 2 2 c21-c5-4xlarge 172.31.18.213 59001 0 2 c11-c5-4xlarge 172.31.21.44 59001 > /dev/null 2>&1 &'"
B32: =B$2&info!E24&" "&CHAR(34)&B$3&CHAR(39)&B$4&" 2 2 "&info!D24&" "&info!E24&" "&B$6&" "&B$7&" "&C$7&" "&info!F24&B$5&CHAR(39)&CHAR(34) -> ssh -i p2pstorage.pem ec2-user@172.31.23.72 "sh -c 'cd node; nohup ./startServer.sh 2 2 c22-t2-small 172.31.23.72 59001 0 2 c21-c5-4xlarge 172.31.18.213 59001 > /dev/null 2>&1 &'"
B33: =B$2&info!E25&" "&CHAR(34)&B$3&CHAR(39)&B$4&" 2 2 "&info!D25&" "&info!E25&" "&B$6&" "&B$7&" "&C$7&" "&info!F25&B$5&CHAR(39)&CHAR(34) -> ssh -i p2pstorage.pem ec2-user@172.31.31.24 "sh -c 'cd node; nohup ./startServer.sh 2 2 c23-t2-small 172.31.31.24 59001 0 2 c21-c5-4xlarge 172.31.18.213 59001 > /dev/null 2>&1 &'"
B34: =B$2&info!E26&" "&CHAR(34)&B$3&CHAR(39)&B$4&" 2 2 "&info!D26&" "&info!E26&" "&B$6&" "&B$7&" "&C$7&" "&info!F26&B$5&CHAR(39)&CHAR(34) -> ssh -i p2pstorage.pem ec2-user@172.31.27.58 "sh -c 'cd node; nohup ./startServer.sh 2 2 c24-t2-small 172.31.27.58 59001 0 2 c21-c5-4xlarge 172.31.18.213 59001 > /dev/null 2>&1 &'"
B35: =B$2&info!E27&" "&CHAR(34)&B$3&CHAR(39)&B$4&" 2 2 "&info!D27&" "&info!E27&" "&B$6&" "&B$7&" "&C$7&" "&info!F27&B$5&CHAR(39)&CHAR(34) -> ssh -i p2pstorage.pem ec2-user@172.31.17.169 "sh -c 'cd node; nohup ./startServer.sh 2 2 c25-t2-medium 172.31.17.169 59001 0 2 c21-c5-4xlarge 172.31.18.213 59001 > /dev/null 2>&1 &'"
B36: =B$2&info!E28&" "&CHAR(34)&B$3&CHAR(39)&B$4&" 2 2 "&info!D28&" "&info!E28&" "&B$6&" "&B$7&" "&C$7&" "&info!F28&B$5&CHAR(39)&CHAR(34) -> ssh -i p2pstorage.pem ec2-user@172.31.28.12 "sh -c 'cd node; nohup ./startServer.sh 2 2 c26-t2-medium 172.31.28.12 59001 0 2 c21-c5-4xlarge 172.31.18.213 59001 > /dev/null 2>&1 &'"
B37: =B$2&info!E29&" "&CHAR(34)&B$3&CHAR(39)&B$4&" 2 2 "&info!D29&" "&info!E29&" "&B$6&" "&B$7&" "&C$7&" "&info!F29&B$5&CHAR(39)&CHAR(34) -> ssh -i p2pstorage.pem ec2-user@172.31.20.85 "sh -c 'cd node; nohup ./startServer.sh 2 2 c27-t2-medium 172.31.20.85 59001 0 2 c21-c5-4xlarge 172.31.18.213 59001 > /dev/null 2>&1 &'"
B38: =B$2&info!E30&" "&CHAR(34)&B$3&CHAR(39)&B$4&" 2 2 "&info!D30&" "&info!E30&" "&B$6&" "&B$7&" "&C$7&" "&info!F30&B$5&CHAR(39)&CHAR(34) -> ssh -i p2pstorage.pem ec2-user@172.31.24.7 "sh -c 'cd node; nohup ./startServer.sh 2 2 c28-c5-xlarge 172.31.24.7 59001 0 2 c21-c5-4xlarge 172.31.18.213 59001 > /dev/null 2>&1 &'"
B39: =B$2&info!E31&" "&CHAR(34)&B$3&CHAR(39)&B$4&" 2 2 "&info!D31&" "&info!E31&" "&B$6&" "&B$7&" "&C$7&" "&info!F31&B$5&CHAR(39)&CHAR(34) -> ssh -i p2pstorage.pem ec2-user@172.31.29.177 "sh -c 'cd node; nohup ./startServer.sh 2 2 c29-c5-xlarge 172.31.29.177 59001 0 2 c21-c5-4xlarge 172.31.18.213 59001 > /dev/null 2>&1 &'"
B40: =B$2&info!E32&" "&CHAR(34)&B$3&CHAR(39)&B$4&" 2 2 "&info!D32&" "&info!E32&" "&B$6&" "&B$7&" "&C$7&" "&info!F32&B$5&CHAR(39)&CHAR(34) -> ssh -i p2pstorage.pem ec2-user@172.31.18.111 "sh -c 'cd node; nohup ./startServer.sh 2 2 c30-c5-2xlarge 172.31.18.111 59001 0 2 c21-c5-4xlarge 172.31.18.213 59001 > /dev/null 2>&1 &'"
B41: =B$2&info!E33&" "&CHAR(34)&B$3&CHAR(39)&B$4&" 2 2 "&info!D33&" "&info!E33&" "&B$6&" "&B$7&" "&C$7&" "&info!F33&B$5&CHAR(39)&CHAR(34) -> ssh -i p2pstorage.pem ec2-user@172.31.18.88 "sh -c 'cd node; nohup ./startServer.sh 2 2 c31-c5-4xlarge 172.31.18.88 59001 0 2 c21-c5-4xlarge 172.31.18.213 59001 > /dev/null 2>&1 &'"
B42: =B$2&info!E34&" "&CHAR(34)&B$3&CHAR(39)&B$4&" 2 2 "&info!D34&" "&info!E34&" "&B$6&" "&B$7&" "&C$7&" "&info!F34&B$5&CHAR(39)&CHAR(34) -> ssh -i p2pstorage.pem ec2-user@172.31.27.94 "sh -c 'cd node; nohup ./startServer.sh 2 2 c32-t2-small 172.31.27.94 59001 0 2 c31-c5-4xlarge 172.31.18.88 59001 > /dev/null 2>&1 &'"
... B50: =B$2&info!E42&" "&CHAR(34)&B$3&CHAR(39)&B$4&" 2 2 "&info!D42&" "&info!E42&" "&B$6&" "&B$7&" "&C$7&" "&info!F42&B$5&CHAR(39)&CHAR(34) -> ssh -i p2pstorage.pem ec2-user@172.31.23.103 "sh -c 'cd node; nohup ./startServer.sh 2 2 c40-c5-2xlarge 172.31.23.103 59001 0 2 c31-c5-4xlarge 172.31.18.88 59001 > /dev/null 2>&1 &'"
B51: sleep 30
B52: =B$2&info!E44&" "&CHAR(34)&B$3&CHAR(39)&B$4&" 2 2 "&info!D44&" "&info!E44&" "&B$6&" "&B$7&" "&C$7&" "&info!F44&B$5&CHAR(39)&CHAR(34) -> ssh -i p2pstorage.pem ec2-user@172.31.29.34 "sh -c 'cd node; nohup ./startServer.sh 2 2 c41-c5-4xlarge 172.31.29.34 59001 0 2 c31-c5-4xlarge 172.31.18.88 59001 > /dev/null 2>&1 &'"
B53: =B$2&info!E45&" "&CHAR(34)&B$3&CHAR(39)&B$4&" 2 2 "&info!D45&" "&info!E45&" "&B$6&" "&B$7&" "&C$7&" "&info!F45&B$5&CHAR(39)&CHAR(34) -> ssh -i p2pstorage.pem ec2-user@172.31.31.208 "sh -c 'cd node; nohup ./startServer.sh 2 2 c42-t2-small 172.31.31.208 59001 0 2 c41-c5-4xlarge 172.31.29.34 59001 > /dev/null 2>&1 &'"
B54: =B$2&info!E46&" "&CHAR(34)&B$3&CHAR(39)&B$4&" 2 2 "&info!D46&" "&info!E46&" "&B$6&" "&B$7&" "&C$7&" "&info!F46&B$5&CHAR(39)&CHAR(34) -> ssh -i p2pstorage.pem ec2-user@172.31.19.51 "sh -c 'cd node; nohup ./startServer.sh 2 2 c43-t2-small 172.31.19.51 59001 0 2 c41-c5-4xlarge 172.31.29.34 59001 > /dev/null 2>&1 &'"
B55: =B$2&info!E47&" "&CHAR(34)&B$3&CHAR(39)&B$4&" 2 2 "&info!D47&" "&info!E47&" "&B$6&" "&B$7&" "&C$7&" "&info!F47&B$5&CHAR(39)&CHAR(34) -> ssh -i p2pstorage.pem ec2-user@172.31.31.54 "sh -c 'cd node; nohup ./startServer.sh 2 2 c44-t2-small 172.31.31.54 59001 0 2 c41-c5-4xlarge 172.31.29.34 59001 > /dev/null 2>&1 &'"
...

Sheet startServerRep
B2: ssh -i p2pstorage.pem ec2-user@
B3: sh -c
B4: cd node; nohup ./startServer.sh
B5: > /dev/null 2>&1 &
B6: 59001
B7: 0 | C7: 2
B9: =B$2&info!E2&" "&CHAR(34)&B$3&CHAR(39)&B$4&" 3 1 "&info!D2&" "&info!E2&" "&B$6&" "&B$7&" "&C$7&" "&info!F2&B$5&CHAR(39)&CHAR(34) -> ssh -i p2pstorage.pem ec2-user@172.31.16.10 "sh -c 'cd node; nohup ./startServer.sh 3 1 c01-c5-4xlarge 172.31.16.10 59001 0 2 0 0 0 > /dev/null 2>&1 &'"
B10: sleep 10
B11: =B$2&info!E3&" "&CHAR(34)&B$3&CHAR(39)&B$4&" 3 2 "&info!D3&" "&info!E3&" "&B$6&" "&B$7&" "&C$7&" "&info!F3&B$5&CHAR(39)&CHAR(34) -> ssh -i p2pstorage.pem ec2-user@172.31.27.28 "sh -c 'cd node; nohup ./startServer.sh 3 2 c02-t2-small 172.31.27.28 59001 0 2 c01-c5-4xlarge 172.31.16.10 59001 > /dev/null 2>&1 &'"
B12: =B$2&info!E4&" "&CHAR(34)&B$3&CHAR(39)&B$4&" 3 2 "&info!D4&" "&info!E4&" "&B$6&" "&B$7&" "&C$7&" "&info!F4&B$5&CHAR(39)&CHAR(34) -> ssh -i p2pstorage.pem ec2-user@172.31.24.48 "sh -c 'cd node; nohup ./startServer.sh 3 2 c03-t2-small 172.31.24.48 59001 0 2 c01-c5-4xlarge 172.31.16.10 59001 > /dev/null 2>&1 &'"
B13: =B$2&info!E5&" "&CHAR(34)&B$3&CHAR(39)&B$4&" 3 2 "&info!D5&" "&info!E5&" "&B$6&" "&B$7&" "&C$7&" "&info!F5&B$5&CHAR(39)&CHAR(34) -> ssh -i p2pstorage.pem ec2-user@172.31.19.20 "sh -c 'cd node; nohup ./startServer.sh 3 2 c04-t2-small 172.31.19.20 59001 0 2 c01-c5-4xlarge 172.31.16.10 59001 > /dev/null 2>&1 &'"
B14: =B$2&info!E6&" "&CHAR(34)&B$3&CHAR(39)&B$4&" 3 2 "&info!D6&" "&info!E6&" "&B$6&" "&B$7&" "&C$7&" "&info!F6&B$5&CHAR(39)&CHAR(34) -> ssh -i p2pstorage.pem ec2-user@172.31.21.44 "sh -c 'cd node; nohup ./startServer.sh 3 2 c05-t2-medium 172.31.21.44 59001 0 2 c01-c5-4xlarge 172.31.16.10 59001 > /dev/null 2>&1 &'"
B15: =B$2&info!E7&" "&CHAR(34)&B$3&CHAR(39)&B$4&" 3 2 "&info!D7&" "&info!E7&" "&B$6&" "&B$7&" "&C$7&" "&info!F7&B$5&CHAR(39)&CHAR(34) -> ssh -i p2pstorage.pem ec2-user@172.31.42.48 "sh -c 'cd node; nohup ./startServer.sh 3 2 c06-t2-medium 172.31.42.48 59001 0 2 c01-c5-4xlarge 172.31.16.10 59001 > /dev/null 2>&1 &'"
B16: =B$2&info!E8&" "&CHAR(34)&B$3&CHAR(39)&B$4&" 3 2 "&info!D8&" "&info!E8&" "&B$6&" "&B$7&" "&C$7&" "&info!F8&B$5&CHAR(39)&CHAR(34) -> ssh -i p2pstorage.pem ec2-user@172.31.6.148 "sh -c 'cd node; nohup ./startServer.sh 3 2 c07-t2-medium 172.31.6.148 59001 0 2 c01-c5-4xlarge 172.31.16.10 59001 > /dev/null 2>&1 &'"
B17: =B$2&info!E9&" "&CHAR(34)&B$3&CHAR(39)&B$4&" 3 2 "&info!D9&" "&info!E9&" "&B$6&" "&B$7&" "&C$7&" "&info!F9&B$5&CHAR(39)&CHAR(34) -> ssh -i p2pstorage.pem ec2-user@172.31.21.20 "sh -c 'cd node; nohup ./startServer.sh 3 2 c08-c5-xlarge 172.31.21.20 59001 0 2 c01-c5-4xlarge 172.31.16.10 59001 > /dev/null 2>&1 &'"
B18: =B$2&info!E10&" "&CHAR(34)&B$3&CHAR(39)&B$4&" 3 2 "&info!D10&" "&info!E10&" "&B$6&" "&B$7&" "&C$7&" "&info!F10&B$5&CHAR(39)&CHAR(34) -> ssh -i p2pstorage.pem ec2-user@172.31.29.51 "sh -c 'cd node; nohup ./startServer.sh 3 2 c09-c5-xlarge 172.31.29.51 59001 0 2 c01-c5-4xlarge 172.31.16.10 59001 > /dev/null 2>&1 &'"
B19: =B$2&info!E11&" "&CHAR(34)&B$3&CHAR(39)&B$4&" 3 2 "&info!D11&" "&info!E11&" "&B$6&" "&B$7&" "&C$7&" "&info!F11&B$5&CHAR(39)&CHAR(34) -> ssh -i p2pstorage.pem ec2-user@172.31.27.113 "sh -c 'cd node; nohup ./startServer.sh 3 2 c10-c5-2xlarge 172.31.27.113 59001 0 2 c01-c5-4xlarge 172.31.16.10 59001 > /dev/null 2>&1 &'"
B20: =B$2&info!E12&" "&CHAR(34)&B$3&CHAR(39)&B$4&" 3 2 "&info!D12&" "&info!E12&" "&B$6&" "&B$7&" "&C$7&" "&info!F12&B$5&CHAR(39)&CHAR(34) -> ssh -i p2pstorage.pem ec2-user@172.31.31.235 "sh -c 'cd node; nohup ./startServer.sh 3 2 c11-c5-4xlarge 172.31.31.235 59001 0 2 c01-c5-4xlarge 172.31.16.10 59001 > /dev/null 2>&1 &'"
B21: =B$2&info!E13&" "&CHAR(34)&B$3&CHAR(39)&B$4&" 3 2 "&info!D13&" "&info!E13&" "&B$6&" "&B$7&" "&C$7&" "&info!F13&B$5&CHAR(39)&CHAR(34) -> ssh -i p2pstorage.pem ec2-user@172.31.23.24 "sh -c 'cd node; nohup ./startServer.sh 3 2 c12-t2-small 172.31.23.24 59001 0 2 c11-c5-4xlarge 172.31.21.44 59001 > /dev/null 2>&1 &'"
B22: =B$2&info!E14&" "&CHAR(34)&B$3&CHAR(39)&B$4&" 3 2 "&info!D14&" "&info!E14&" "&B$6&" "&B$7&" "&C$7&" "&info!F14&B$5&CHAR(39)&CHAR(34) -> ssh -i p2pstorage.pem ec2-user@172.31.28.220 "sh -c 'cd node; nohup ./startServer.sh 3 2 c13-t2-small 172.31.28.220 59001 0 2 c11-c5-4xlarge 172.31.21.44 59001 > /dev/null 2>&1 &'"
... B29: =B$2&info!E21&" "&CHAR(34)&B$3&CHAR(39)&B$4&" 3 2 "&info!D21&" "&info!E21&" "&B$6&" "&B$7&" "&C$7&" "&info!F21&B$5&CHAR(39)&CHAR(34) -> ssh -i p2pstorage.pem ec2-user@172.31.25.39 "sh -c 'cd node; nohup ./startServer.sh 3 2 c20-c5-2xlarge 172.31.25.39 59001 0 2 c11-c5-4xlarge 172.31.21.44 59001 > /dev/null 2>&1 &'"
B30: sleep 30
B31: =B$2&info!E23&" "&CHAR(34)&B$3&CHAR(39)&B$4&" 3 2 "&info!D23&" "&info!E23&" "&B$6&" "&B$7&" "&C$7&" "&info!F23&B$5&CHAR(39)&CHAR(34) -> ssh -i p2pstorage.pem ec2-user@172.31.18.213 "sh -c 'cd node; nohup ./startServer.sh 3 2 c21-c5-4xlarge 172.31.18.213 59001 0 2 c11-c5-4xlarge 172.31.21.44 59001 > /dev/null 2>&1 &'"
B32: =B$2&info!E24&" "&CHAR(34)&B$3&CHAR(39)&B$4&" 3 2 "&info!D24&" "&info!E24&" "&B$6&" "&B$7&" "&C$7&" "&info!F24&B$5&CHAR(39)&CHAR(34) -> ssh -i p2pstorage.pem ec2-user@172.31.23.72 "sh -c 'cd node; nohup ./startServer.sh 3 2 c22-t2-small 172.31.23.72 59001 0 2 c21-c5-4xlarge 172.31.18.213 59001 > /dev/null 2>&1 &'"
B33: =B$2&info!E25&" "&CHAR(34)&B$3&CHAR(39)&B$4&" 3 2 "&info!D25&" "&info!E25&" "&B$6&" "&B$7&" "&C$7&" "&info!F25&B$5&CHAR(39)&CHAR(34) -> ssh -i p2pstorage.pem ec2-user@172.31.31.24 "sh -c 'cd node; nohup ./startServer.sh 3 2 c23-t2-small 172.31.31.24 59001 0 2 c21-c5-4xlarge 172.31.18.213 59001 > /dev/null 2>&1 &'"
B34: =B$2&info!E26&" "&CHAR(34)&B$3&CHAR(39)&B$4&" 3 2 "&info!D26&" "&info!E26&" "&B$6&" "&B$7&" "&C$7&" "&info!F26&B$5&CHAR(39)&CHAR(34) -> ssh -i p2pstorage.pem ec2-user@172.31.27.58 "sh -c 'cd node; nohup ./startServer.sh 3 2 c24-t2-small 172.31.27.58 59001 0 2 c21-c5-4xlarge 172.31.18.213 59001 > /dev/null 2>&1 &'"
B35: =B$2&info!E27&" "&CHAR(34)&B$3&CHAR(39)&B$4&" 3 2 "&info!D27&" "&info!E27&" "&B$6&" "&B$7&" "&C$7&" "&info!F27&B$5&CHAR(39)&CHAR(34) -> ssh -i p2pstorage.pem ec2-user@172.31.17.169 "sh -c 'cd node; nohup ./startServer.sh 3 2 c25-t2-medium 172.31.17.169 59001 0 2 c21-c5-4xlarge 172.31.18.213 59001 > /dev/null 2>&1 &'"
B36: =B$2&info!E28&" "&CHAR(34)&B$3&CHAR(39)&B$4&" 3 2 "&info!D28&" "&info!E28&" "&B$6&" "&B$7&" "&C$7&" "&info!F28&B$5&CHAR(39)&CHAR(34) -> ssh -i p2pstorage.pem ec2-user@172.31.28.12 "sh -c 'cd node; nohup ./startServer.sh 3 2 c26-t2-medium 172.31.28.12 59001 0 2 c21-c5-4xlarge 172.31.18.213 59001 > /dev/null 2>&1 &'"
B37: =B$2&info!E29&" "&CHAR(34)&B$3&CHAR(39)&B$4&" 3 2 "&info!D29&" "&info!E29&" "&B$6&" "&B$7&" "&C$7&" "&info!F29&B$5&CHAR(39)&CHAR(34) -> ssh -i p2pstorage.pem ec2-user@172.31.20.85 "sh -c 'cd node; nohup ./startServer.sh 3 2 c27-t2-medium 172.31.20.85 59001 0 2 c21-c5-4xlarge 172.31.18.213 59001 > /dev/null 2>&1 &'"
B38: =B$2&info!E30&" "&CHAR(34)&B$3&CHAR(39)&B$4&" 3 2 "&info!D30&" "&info!E30&" "&B$6&" "&B$7&" "&C$7&" "&info!F30&B$5&CHAR(39)&CHAR(34) -> ssh -i p2pstorage.pem ec2-user@172.31.24.7 "sh -c 'cd node; nohup ./startServer.sh 3 2 c28-c5-xlarge 172.31.24.7 59001 0 2 c21-c5-4xlarge 172.31.18.213 59001 > /dev/null 2>&1 &'"
B39: =B$2&info!E31&" "&CHAR(34)&B$3&CHAR(39)&B$4&" 3 2 "&info!D31&" "&info!E31&" "&B$6&" "&B$7&" "&C$7&" "&info!F31&B$5&CHAR(39)&CHAR(34) -> ssh -i p2pstorage.pem ec2-user@172.31.29.177 "sh -c 'cd node; nohup ./startServer.sh 3 2 c29-c5-xlarge 172.31.29.177 59001 0 2 c21-c5-4xlarge 172.31.18.213 59001 > /dev/null 2>&1 &'"
B40: =B$2&info!E32&" "&CHAR(34)&B$3&CHAR(39)&B$4&" 3 2 "&info!D32&" "&info!E32&" "&B$6&" "&B$7&" "&C$7&" "&info!F32&B$5&CHAR(39)&CHAR(34) -> ssh -i p2pstorage.pem ec2-user@172.31.18.111 "sh -c 'cd node; nohup ./startServer.sh 3 2 c30-c5-2xlarge 172.31.18.111 59001 0 2 c21-c5-4xlarge 172.31.18.213 59001 > /dev/null 2>&1 &'"
B41: =B$2&info!E33&" "&CHAR(34)&B$3&CHAR(39)&B$4&" 3 2 "&info!D33&" "&info!E33&" "&B$6&" "&B$7&" "&C$7&" "&info!F33&B$5&CHAR(39)&CHAR(34) -> ssh -i p2pstorage.pem ec2-user@172.31.18.88 "sh -c 'cd node; nohup ./startServer.sh 3 2 c31-c5-4xlarge 172.31.18.88 59001 0 2 c21-c5-4xlarge 172.31.18.213 59001 > /dev/null 2>&1 &'"
B42: =B$2&info!E34&" "&CHAR(34)&B$3&CHAR(39)&B$4&" 3 2 "&info!D34&" "&info!E34&" "&B$6&" "&B$7&" "&C$7&" "&info!F34&B$5&CHAR(39)&CHAR(34) -> ssh -i p2pstorage.pem ec2-user@172.31.27.94 "sh -c 'cd node; nohup ./startServer.sh 3 2 c32-t2-small 172.31.27.94 59001 0 2 c31-c5-4xlarge 172.31.18.88 59001 > /dev/null 2>&1 &'"
... B50: =B$2&info!E42&" "&CHAR(34)&B$3&CHAR(39)&B$4&" 3 2 "&info!D42&" "&info!E42&" "&B$6&" "&B$7&" "&C$7&" "&info!F42&B$5&CHAR(39)&CHAR(34) -> ssh -i p2pstorage.pem ec2-user@172.31.23.103 "sh -c 'cd node; nohup ./startServer.sh 3 2 c40-c5-2xlarge 172.31.23.103 59001 0 2 c31-c5-4xlarge 172.31.18.88 59001 > /dev/null 2>&1 &'"
B51: sleep 30
B52: =B$2&info!E44&" "&CHAR(34)&B$3&CHAR(39)&B$4&" 3 2 "&info!D44&" "&info!E44&" "&B$6&" "&B$7&" "&C$7&" "&info!F44&B$5&CHAR(39)&CHAR(34) -> ssh -i p2pstorage.pem ec2-user@172.31.29.34 "sh -c 'cd node; nohup ./startServer.sh 3 2 c41-c5-4xlarge 172.31.29.34 59001 0 2 c31-c5-4xlarge 172.31.18.88 59001 > /dev/null 2>&1 &'"
B53: =B$2&info!E45&" "&CHAR(34)&B$3&CHAR(39)&B$4&" 3 2 "&info!D45&" "&info!E45&" "&B$6&" "&B$7&" "&C$7&" "&info!F45&B$5&CHAR(39)&CHAR(34) -> ssh -i p2pstorage.pem ec2-user@172.31.31.208 "sh -c 'cd node; nohup ./startServer.sh 3 2 c42-t2-small 172.31.31.208 59001 0 2 c41-c5-4xlarge 172.31.29.34 59001 > /dev/null 2>&1 &'"
B54: =B$2&info!E46&" "&CHAR(34)&B$3&CHAR(39)&B$4&" 3 2 "&info!D46&" "&info!E46&" "&B$6&" "&B$7&" "&C$7&" "&info!F46&B$5&CHAR(39)&CHAR(34) -> ssh -i p2pstorage.pem ec2-user@172.31.19.51 "sh -c 'cd node; nohup ./startServer.sh 3 2 c43-t2-small 172.31.19.51 59001 0 2 c41-c5-4xlarge 172.31.29.34 59001 > /dev/null 2>&1 &'"
B55: =B$2&info!E47&" "&CHAR(34)&B$3&CHAR(39)&B$4&" 3 2 "&info!D47&" "&info!E47&" "&B$6&" "&B$7&" "&C$7&" "&info!F47&B$5&CHAR(39)&CHAR(34) -> ssh -i p2pstorage.pem ec2-user@172.31.31.54 "sh -c 'cd node; nohup ./startServer.sh 3 2 c44-t2-small 172.31.31.54 59001 0 2 c41-c5-4xlarge 172.31.29.34 59001 > /dev/null 2>&1 &'"
...

Sheet startServerPT
B2: ssh -i p2pstorage.pem ec2-user@
B3: sh -c
B4: cd node; nohup ./startServer.sh
B5: > /dev/null 2>&1 &
B6: 59001
B7: 0 | C7: 2
B9: =B$2&info!E2&" "&CHAR(34)&B$3&CHAR(39)&B$4&" 4 1 "&info!D2&" "&info!E2&" "&B$6&" "&B$7&" "&C$7&" "&info!F2&B$5&CHAR(39)&CHAR(34) -> ssh -i p2pstorage.pem ec2-user@172.31.16.10 "sh -c 'cd node; nohup ./startServer.sh 4 1 c01-c5-4xlarge 172.31.16.10 59001 0 2 0 0 0 > /dev/null 2>&1 &'"
B10: sleep 10
B11: =B$2&info!E3&" "&CHAR(34)&B$3&CHAR(39)&B$4&" 4 2 "&info!D3&" "&info!E3&" "&B$6&" "&B$7&" "&C$7&" "&info!F3&B$5&CHAR(39)&CHAR(34) -> ssh -i p2pstorage.pem ec2-user@172.31.27.28 "sh -c 'cd node; nohup ./startServer.sh 4 2 c02-t2-small 172.31.27.28 59001 0 2 c01-c5-4xlarge 172.31.16.10 59001 > /dev/null 2>&1 &'"
B12: =B$2&info!E4&" "&CHAR(34)&B$3&CHAR(39)&B$4&" 4 2 "&info!D4&" "&info!E4&" "&B$6&" "&B$7&" "&C$7&" "&info!F4&B$5&CHAR(39)&CHAR(34) -> ssh -i p2pstorage.pem ec2-user@172.31.24.48 "sh -c 'cd node; nohup ./startServer.sh 4 2 c03-t2-small 172.31.24.48 59001 0 2 c01-c5-4xlarge 172.31.16.10 59001 > /dev/null 2>&1 &'"
B13: =B$2&info!E5&" "&CHAR(34)&B$3&CHAR(39)&B$4&" 4 2 "&info!D5&" "&info!E5&" "&B$6&" "&B$7&" "&C$7&" "&info!F5&B$5&CHAR(39)&CHAR(34) -> ssh -i p2pstorage.pem ec2-user@172.31.19.20 "sh -c 'cd node; nohup ./startServer.sh 4 2 c04-t2-small 172.31.19.20 59001 0 2 c01-c5-4xlarge 172.31.16.10 59001 > /dev/null 2>&1 &'"
B14: =B$2&info!E6&" "&CHAR(34)&B$3&CHAR(39)&B$4&" 4 2 "&info!D6&" "&info!E6&" "&B$6&" "&B$7&" "&C$7&" "&info!F6&B$5&CHAR(39)&CHAR(34) -> ssh -i p2pstorage.pem ec2-user@172.31.21.44 "sh -c 'cd node; nohup ./startServer.sh 4 2 c05-t2-medium 172.31.21.44 59001 0 2 c01-c5-4xlarge 172.31.16.10 59001 > /dev/null 2>&1 &'"
B15: =B$2&info!E7&" "&CHAR(34)&B$3&CHAR(39)&B$4&" 4 2 "&info!D7&" "&info!E7&" "&B$6&" "&B$7&" "&C$7&" "&info!F7&B$5&CHAR(39)&CHAR(34) -> ssh -i p2pstorage.pem ec2-user@172.31.42.48 "sh -c 'cd node; nohup ./startServer.sh 4 2 c06-t2-medium 172.31.42.48 59001 0 2 c01-c5-4xlarge 172.31.16.10 59001 > /dev/null 2>&1 &'"
B16: =B$2&info!E8&" "&CHAR(34)&B$3&CHAR(39)&B$4&" 4 2 "&info!D8&" "&info!E8&" "&B$6&" "&B$7&" "&C$7&" "&info!F8&B$5&CHAR(39)&CHAR(34) -> ssh -i p2pstorage.pem ec2-user@172.31.6.148 "sh -c 'cd node; nohup ./startServer.sh 4 2 c07-t2-medium 172.31.6.148 59001 0 2 c01-c5-4xlarge 172.31.16.10 59001 > /dev/null 2>&1 &'"
B17: =B$2&info!E9&" "&CHAR(34)&B$3&CHAR(39)&B$4&" 4 2 "&info!D9&" "&info!E9&" "&B$6&" "&B$7&" "&C$7&" "&info!F9&B$5&CHAR(39)&CHAR(34) -> ssh -i p2pstorage.pem ec2-user@172.31.21.20 "sh -c 'cd node; nohup ./startServer.sh 4 2 c08-c5-xlarge 172.31.21.20 59001 0 2 c01-c5-4xlarge 172.31.16.10 59001 > /dev/null 2>&1 &'"
B18: =B$2&info!E10&" "&CHAR(34)&B$3&CHAR(39)&B$4&" 4 2 "&info!D10&" "&info!E10&" "&B$6&" "&B$7&" "&C$7&" "&info!F10&B$5&CHAR(39)&CHAR(34) -> ssh -i p2pstorage.pem ec2-user@172.31.29.51 "sh -c 'cd node; nohup ./startServer.sh 4 2 c09-c5-xlarge 172.31.29.51 59001 0 2 c01-c5-4xlarge 172.31.16.10 59001 > /dev/null 2>&1 &'"
B19: =B$2&info!E11&" "&CHAR(34)&B$3&CHAR(39)&B$4&" 4 2 "&info!D11&" "&info!E11&" "&B$6&" "&B$7&" "&C$7&" "&info!F11&B$5&CHAR(39)&CHAR(34) -> ssh -i p2pstorage.pem ec2-user@172.31.27.113 "sh -c 'cd node; nohup ./startServer.sh 4 2 c10-c5-2xlarge 172.31.27.113 59001 0 2 c01-c5-4xlarge 172.31.16.10 59001 > /dev/null 2>&1 &'"
B20: =B$2&info!E12&" "&CHAR(34)&B$3&CHAR(39)&B$4&" 4 2 "&info!D12&" "&info!E12&" "&B$6&" "&B$7&" "&C$7&" "&info!F12&B$5&CHAR(39)&CHAR(34) -> ssh -i p2pstorage.pem ec2-user@172.31.31.235 "sh -c 'cd node; nohup ./startServer.sh 4 2 c11-c5-4xlarge 172.31.31.235 59001 0 2 c01-c5-4xlarge 172.31.16.10 59001 > /dev/null 2>&1 &'"
B21: =B$2&info!E13&" "&CHAR(34)&B$3&CHAR(39)&B$4&" 4 2 "&info!D13&" "&info!E13&" "&B$6&" "&B$7&" "&C$7&" "&info!F13&B$5&CHAR(39)&CHAR(34) -> ssh -i p2pstorage.pem ec2-user@172.31.23.24 "sh -c 'cd node; nohup ./startServer.sh 4 2 c12-t2-small 172.31.23.24 59001 0 2 c11-c5-4xlarge 172.31.21.44 59001 > /dev/null 2>&1 &'"
B22: =B$2&info!E14&" "&CHAR(34)&B$3&CHAR(39)&B$4&" 4 2 "&info!D14&" "&info!E14&" "&B$6&" "&B$7&" "&C$7&" "&info!F14&B$5&CHAR(39)&CHAR(34) -> ssh -i p2pstorage.pem ec2-user@172.31.28.220 "sh -c 'cd node; nohup ./startServer.sh 4 2 c13-t2-small 172.31.28.220 59001 0 2 c11-c5-4xlarge 172.31.21.44 59001 > /dev/null 2>&1 &'"
... B29: =B$2&info!E21&" "&CHAR(34)&B$3&CHAR(39)&B$4&" 4 2 "&info!D21&" "&info!E21&" "&B$6&" "&B$7&" "&C$7&" "&info!F21&B$5&CHAR(39)&CHAR(34) -> ssh -i p2pstorage.pem ec2-user@172.31.25.39 "sh -c 'cd node; nohup ./startServer.sh 4 2 c20-c5-2xlarge 172.31.25.39 59001 0 2 c11-c5-4xlarge 172.31.21.44 59001 > /dev/null 2>&1 &'"
B30: sleep 30
B31: =B$2&info!E23&" "&CHAR(34)&B$3&CHAR(39)&B$4&" 4 2 "&info!D23&" "&info!E23&" "&B$6&" "&B$7&" "&C$7&" "&info!F23&B$5&CHAR(39)&CHAR(34) -> ssh -i p2pstorage.pem ec2-user@172.31.18.213 "sh -c 'cd node; nohup ./startServer.sh 4 2 c21-c5-4xlarge 172.31.18.213 59001 0 2 c11-c5-4xlarge 172.31.21.44 59001 > /dev/null 2>&1 &'"
B32: =B$2&info!E24&" "&CHAR(34)&B$3&CHAR(39)&B$4&" 4 2 "&info!D24&" "&info!E24&" "&B$6&" "&B$7&" "&C$7&" "&info!F24&B$5&CHAR(39)&CHAR(34) -> ssh -i p2pstorage.pem ec2-user@172.31.23.72 "sh -c 'cd node; nohup ./startServer.sh 4 2 c22-t2-small 172.31.23.72 59001 0 2 c21-c5-4xlarge 172.31.18.213 59001 > /dev/null 2>&1 &'"
B33: =B$2&info!E25&" "&CHAR(34)&B$3&CHAR(39)&B$4&" 4 2 "&info!D25&" "&info!E25&" "&B$6&" "&B$7&" "&C$7&" "&info!F25&B$5&CHAR(39)&CHAR(34) -> ssh -i p2pstorage.pem ec2-user@172.31.31.24 "sh -c 'cd node; nohup ./startServer.sh 4 2 c23-t2-small 172.31.31.24 59001 0 2 c21-c5-4xlarge 172.31.18.213 59001 > /dev/null 2>&1 &'"
B34: =B$2&info!E26&" "&CHAR(34)&B$3&CHAR(39)&B$4&" 4 2 "&info!D26&" "&info!E26&" "&B$6&" "&B$7&" "&C$7&" "&info!F26&B$5&CHAR(39)&CHAR(34) -> ssh -i p2pstorage.pem ec2-user@172.31.27.58 "sh -c 'cd node; nohup ./startServer.sh 4 2 c24-t2-small 172.31.27.58 59001 0 2 c21-c5-4xlarge 172.31.18.213 59001 > /dev/null 2>&1 &'"
B35: =B$2&info!E27&" "&CHAR(34)&B$3&CHAR(39)&B$4&" 4 2 "&info!D27&" "&info!E27&" "&B$6&" "&B$7&" "&C$7&" "&info!F27&B$5&CHAR(39)&CHAR(34) -> ssh -i p2pstorage.pem ec2-user@172.31.17.169 "sh -c 'cd node; nohup ./startServer.sh 4 2 c25-t2-medium 172.31.17.169 59001 0 2 c21-c5-4xlarge 172.31.18.213 59001 > /dev/null 2>&1 &'"
B36: =B$2&info!E28&" "&CHAR(34)&B$3&CHAR(39)&B$4&" 4 2 "&info!D28&" "&info!E28&" "&B$6&" "&B$7&" "&C$7&" "&info!F28&B$5&CHAR(39)&CHAR(34) -> ssh -i p2pstorage.pem ec2-user@172.31.28.12 "sh -c 'cd node; nohup ./startServer.sh 4 2 c26-t2-medium 172.31.28.12 59001 0 2 c21-c5-4xlarge 172.31.18.213 59001 > /dev/null 2>&1 &'"
B37: =B$2&info!E29&" "&CHAR(34)&B$3&CHAR(39)&B$4&" 4 2 "&info!D29&" "&info!E29&" "&B$6&" "&B$7&" "&C$7&" "&info!F29&B$5&CHAR(39)&CHAR(34) -> ssh -i p2pstorage.pem ec2-user@172.31.20.85 "sh -c 'cd node; nohup ./startServer.sh 4 2 c27-t2-medium 172.31.20.85 59001 0 2 c21-c5-4xlarge 172.31.18.213 59001 > /dev/null 2>&1 &'"
B38: =B$2&info!E30&" "&CHAR(34)&B$3&CHAR(39)&B$4&" 4 2 "&info!D30&" "&info!E30&" "&B$6&" "&B$7&" "&C$7&" "&info!F30&B$5&CHAR(39)&CHAR(34) -> ssh -i p2pstorage.pem ec2-user@172.31.24.7 "sh -c 'cd node; nohup ./startServer.sh 4 2 c28-c5-xlarge 172.31.24.7 59001 0 2 c21-c5-4xlarge 172.31.18.213 59001 > /dev/null 2>&1 &'"
B39: =B$2&info!E31&" "&CHAR(34)&B$3&CHAR(39)&B$4&" 4 2 "&info!D31&" "&info!E31&" "&B$6&" "&B$7&" "&C$7&" "&info!F31&B$5&CHAR(39)&CHAR(34) -> ssh -i p2pstorage.pem ec2-user@172.31.29.177 "sh -c 'cd node; nohup ./startServer.sh 4 2 c29-c5-xlarge 172.31.29.177 59001 0 2 c21-c5-4xlarge 172.31.18.213 59001 > /dev/null 2>&1 &'"
B40: =B$2&info!E32&" "&CHAR(34)&B$3&CHAR(39)&B$4&" 4 2 "&info!D32&" "&info!E32&" "&B$6&" "&B$7&" "&C$7&" "&info!F32&B$5&CHAR(39)&CHAR(34) -> ssh -i p2pstorage.pem ec2-user@172.31.18.111 "sh -c 'cd node; nohup ./startServer.sh 4 2 c30-c5-2xlarge 172.31.18.111 59001 0 2 c21-c5-4xlarge 172.31.18.213 59001 > /dev/null 2>&1 &'"
B41: =B$2&info!E33&" "&CHAR(34)&B$3&CHAR(39)&B$4&" 4 2 "&info!D33&" "&info!E33&" "&B$6&" "&B$7&" "&C$7&" "&info!F33&B$5&CHAR(39)&CHAR(34) -> ssh -i p2pstorage.pem ec2-user@172.31.18.88 "sh -c 'cd node; nohup ./startServer.sh 4 2 c31-c5-4xlarge 172.31.18.88 59001 0 2 c21-c5-4xlarge 172.31.18.213 59001 > /dev/null 2>&1 &'"
B42: =B$2&info!E34&" "&CHAR(34)&B$3&CHAR(39)&B$4&" 4 2 "&info!D34&" "&info!E34&" "&B$6&" "&B$7&" "&C$7&" "&info!F34&B$5&CHAR(39)&CHAR(34) -> ssh -i p2pstorage.pem ec2-user@172.31.27.94 "sh -c 'cd node; nohup ./startServer.sh 4 2 c32-t2-small 172.31.27.94 59001 0 2 c31-c5-4xlarge 172.31.18.88 59001 > /dev/null 2>&1 &'"
... B50: =B$2&info!E42&" "&CHAR(34)&B$3&CHAR(39)&B$4&" 4 2 "&info!D42&" "&info!E42&" "&B$6&" "&B$7&" "&C$7&" "&info!F42&B$5&CHAR(39)&CHAR(34) -> ssh -i p2pstorage.pem ec2-user@172.31.23.103 "sh -c 'cd node; nohup ./startServer.sh 4 2 c40-c5-2xlarge 172.31.23.103 59001 0 2 c31-c5-4xlarge 172.31.18.88 59001 > /dev/null 2>&1 &'"
B51: sleep 30
B52: =B$2&info!E44&" "&CHAR(34)&B$3&CHAR(39)&B$4&" 4 2 "&info!D44&" "&info!E44&" "&B$6&" "&B$7&" "&C$7&" "&info!F44&B$5&CHAR(39)&CHAR(34) -> ssh -i p2pstorage.pem ec2-user@172.31.29.34 "sh -c 'cd node; nohup ./startServer.sh 4 2 c41-c5-4xlarge 172.31.29.34 59001 0 2 c31-c5-4xlarge 172.31.18.88 59001 > /dev/null 2>&1 &'"
B53: =B$2&info!E45&" "&CHAR(34)&B$3&CHAR(39)&B$4&" 4 2 "&info!D45&" "&info!E45&" "&B$6&" "&B$7&" "&C$7&" "&info!F45&B$5&CHAR(39)&CHAR(34) -> ssh -i p2pstorage.pem ec2-user@172.31.31.208 "sh -c 'cd node; nohup ./startServer.sh 4 2 c42-t2-small 172.31.31.208 59001 0 2 c41-c5-4xlarge 172.31.29.34 59001 > /dev/null 2>&1 &'"
B54: =B$2&info!E46&" "&CHAR(34)&B$3&CHAR(39)&B$4&" 4 2 "&info!D46&" "&info!E46&" "&B$6&" "&B$7&" "&C$7&" "&info!F46&B$5&CHAR(39)&CHAR(34) -> ssh -i p2pstorage.pem ec2-user@172.31.19.51 "sh -c 'cd node; nohup ./startServer.sh 4 2 c43-t2-small 172.31.19.51 59001 0 2 c41-c5-4xlarge 172.31.29.34 59001 > /dev/null 2>&1 &'"
B55: =B$2&info!E47&" "&CHAR(34)&B$3&CHAR(39)&B$4&" 4 2 "&info!D47&" "&info!E47&" "&B$6&" "&B$7&" "&C$7&" "&info!F47&B$5&CHAR(39)&CHAR(34) -> ssh -i p2pstorage.pem ec2-user@172.31.31.54 "sh -c 'cd node; nohup ./startServer.sh 4 2 c44-t2-small 172.31.31.54 59001 0 2 c41-c5-4xlarge 172.31.29.34 59001 > /dev/null 2>&1 &'"
...

Sheet stopServer
B2: ssh -i p2pstorage.pem ec2-user@
B3: sh -c
B4: cd node; nohup ./stopServer.sh
B5: > /dev/null 2>&1 &
B7: =B$2&info!E2&" "&CHAR(34)&B$3&CHAR(39)&B$4&B$5&CHAR(39)&CHAR(34) -> ssh -i p2pstorage.pem ec2-user@172.31.16.10 "sh -c 'cd node; nohup ./stopServer.sh > /dev/null 2>&1 &'"
B8: =B$2&info!E3&" "&CHAR(34)&B$3&CHAR(39)&B$4&B$5&CHAR(39)&CHAR(34) -> ssh -i p2pstorage.pem ec2-user@172.31.27.28 "sh -c 'cd node; nohup ./stopServer.sh > /dev/null 2>&1 &'"
B9: =B$2&info!E4&" "&CHAR(34)&B$3&CHAR(39)&B$4&B$5&CHAR(39)&CHAR(34) -> ssh -i p2pstorage.pem ec2-user@172.31.24.48 "sh -c 'cd node; nohup ./stopServer.sh > /dev/null 2>&1 &'"
B10: =B$2&info!E5&" "&CHAR(34)&B$3&CHAR(39)&B$4&B$5&CHAR(39)&CHAR(34) -> ssh -i p2pstorage.pem ec2-user@172.31.19.20 "sh -c 'cd node; nohup ./stopServer.sh > /dev/null 2>&1 &'"
B11: =B$2&info!E6&" "&CHAR(34)&B$3&CHAR(39)&B$4&B$5&CHAR(39)&CHAR(34) -> ssh -i p2pstorage.pem ec2-user@172.31.21.44 "sh -c 'cd node; nohup ./stopServer.sh > /dev/null 2>&1 &'"
B12: =B$2&info!E7&" "&CHAR(34)&B$3&CHAR(39)&B$4&B$5&CHAR(39)&CHAR(34) -> ssh -i p2pstorage.pem ec2-user@172.31.42.48 "sh -c 'cd node; nohup ./stopServer.sh > /dev/null 2>&1 &'"
B13: =B$2&info!E8&" "&CHAR(34)&B$3&CHAR(39)&B$4&B$5&CHAR(39)&CHAR(34) -> ssh -i p2pstorage.pem ec2-user@172.31.6.148 "sh -c 'cd node; nohup ./stopServer.sh > /dev/null 2>&1 &'"
B14: =B$2&info!E9&" "&CHAR(34)&B$3&CHAR(39)&B$4&B$5&CHAR(39)&CHAR(34) -> ssh -i p2pstorage.pem ec2-user@172.31.21.20 "sh -c 'cd node; nohup ./stopServer.sh > /dev/null 2>&1 &'"
B15: =B$2&info!E10&" "&CHAR(34)&B$3&CHAR(39)&B$4&B$5&CHAR(39)&CHAR(34) -> ssh -i p2pstorage.pem ec2-user@172.31.29.51 "sh -c 'cd node; nohup ./stopServer.sh > /dev/null 2>&1 &'"
B16: =B$2&info!E11&" "&CHAR(34)&B$3&CHAR(39)&B$4&B$5&CHAR(39)&CHAR(34) -> ssh -i p2pstorage.pem ec2-user@172.31.27.113 "sh -c 'cd node; nohup ./stopServer.sh > /dev/null 2>&1 &'"
B17: =B$2&info!E12&" "&CHAR(34)&B$3&CHAR(39)&B$4&B$5&CHAR(39)&CHAR(34) -> ssh -i p2pstorage.pem ec2-user@172.31.31.235 "sh -c 'cd node; nohup ./stopServer.sh > /dev/null 2>&1 &'"
B18: =B$2&info!E13&" "&CHAR(34)&B$3&CHAR(39)&B$4&B$5&CHAR(39)&CHAR(34) -> ssh -i p2pstorage.pem ec2-user@172.31.23.24 "sh -c 'cd node; nohup ./stopServer.sh > /dev/null 2>&1 &'"
... B110: =B$2&info!E105&" "&CHAR(34)&B$3&CHAR(39)&B$4&B$5&CHAR(39)&CHAR(34) -> ssh -i p2pstorage.pem ec2-user@172.31.28.55 "sh -c 'cd node; nohup ./stopServer.sh > /dev/null 2>&1 &'"

Sheet uploadLib
B2: sftp -i p2pstorage.pem ec2-user@ | H2: sftp -i ../../p2pstorage.pem ec2-user@172.31.16.10:/home/ec2-user/node <<< $'mput *'
B3: :node/lib <<< $
B4: mput upload/lib/*
B7: =B$2&info!E2&B$3&CHAR(39)&B$4&CHAR(39) -> sftp -i p2pstorage.pem ec2-user@172.31.16.10:node/lib <<< $'mput upload/lib/*'
B8: =B$2&info!E3&B$3&CHAR(39)&B$4&CHAR(39) -> sftp -i p2pstorage.pem ec2-user@172.31.27.28:node/lib <<< $'mput upload/lib/*'
B9: =B$2&info!E4&B$3&CHAR(39)&B$4&CHAR(39) -> sftp -i p2pstorage.pem ec2-user@172.31.24.48:node/lib <<< $'mput upload/lib/*'
B10: =B$2&info!E5&B$3&CHAR(39)&B$4&CHAR(39) -> sftp -i p2pstorage.pem ec2-user@172.31.19.20:node/lib <<< $'mput upload/lib/*'
B11: =B$2&info!E6&B$3&CHAR(39)&B$4&CHAR(39) -> sftp -i p2pstorage.pem ec2-user@172.31.21.44:node/lib <<< $'mput upload/lib/*'
B12: =B$2&info!E7&B$3&CHAR(39)&B$4&CHAR(39) -> sftp -i p2pstorage.pem ec2-user@172.31.42.48:node/lib <<< $'mput upload/lib/*'
B13: =B$2&info!E8&B$3&CHAR(39)&B$4&CHAR(39) -> sftp -i p2pstorage.pem ec2-user@172.31.6.148:node/lib <<< $'mput upload/lib/*'
B14: =B$2&info!E9&B$3&CHAR(39)&B$4&CHAR(39) -> sftp -i p2pstorage.pem ec2-user@172.31.21.20:node/lib <<< $'mput upload/lib/*'
B15: =B$2&info!E10&B$3&CHAR(39)&B$4&CHAR(39) -> sftp -i p2pstorage.pem ec2-user@172.31.29.51:node/lib <<< $'mput upload/lib/*'
B16: =B$2&info!E11&B$3&CHAR(39)&B$4&CHAR(39) -> sftp -i p2pstorage.pem ec2-user@172.31.27.113:node/lib <<< $'mput upload/lib/*'
B17: =B$2&info!E12&B$3&CHAR(39)&B$4&CHAR(39) -> sftp -i p2pstorage.pem ec2-user@172.31.31.235:node/lib <<< $'mput upload/lib/*'
B18: =B$2&info!E13&B$3&CHAR(39)&B$4&CHAR(39) -> sftp -i p2pstorage.pem ec2-user@172.31.23.24:node/lib <<< $'mput upload/lib/*'
... B110: =B$2&info!E105&B$3&CHAR(39)&B$4&CHAR(39) -> sftp -i p2pstorage.pem ec2-user@172.31.28.55:node/lib <<< $'mput upload/lib/*'

Sheet uploadFiles
B2: sftp -i p2pstorage.pem ec2-user@ | H2: sftp -i ../../p2pstorage.pem ec2-user@172.31.16.10:/home/ec2-user/node <<< $'mput *'
B3: :node <<< $
B4: mput upload/*
B7: =B$2&info!E2&B$3&CHAR(39)&B$4&CHAR(39) -> sftp -i p2pstorage.pem ec2-user@172.31.16.10:node <<< $'mput upload/*'
B8: =B$2&info!E3&B$3&CHAR(39)&B$4&CHAR(39) -> sftp -i p2pstorage.pem ec2-user@172.31.27.28:node <<< $'mput upload/*'
B9: =B$2&info!E4&B$3&CHAR(39)&B$4&CHAR(39) -> sftp -i p2pstorage.pem ec2-user@172.31.24.48:node <<< $'mput upload/*'
B10: =B$2&info!E5&B$3&CHAR(39)&B$4&CHAR(39) -> sftp -i p2pstorage.pem ec2-user@172.31.19.20:node <<< $'mput upload/*'
B11: =B$2&info!E6&B$3&CHAR(39)&B$4&CHAR(39) -> sftp -i p2pstorage.pem ec2-user@172.31.21.44:node <<< $'mput upload/*'
B12: =B$2&info!E7&B$3&CHAR(39)&B$4&CHAR(39) -> sftp -i p2pstorage.pem ec2-user@172.31.42.48:node <<< $'mput upload/*'
B13: =B$2&info!E8&B$3&CHAR(39)&B$4&CHAR(39) -> sftp -i p2pstorage.pem ec2-user@172.31.6.148:node <<< $'mput upload/*'
B14: =B$2&info!E9&B$3&CHAR(39)&B$4&CHAR(39) -> sftp -i p2pstorage.pem ec2-user@172.31.21.20:node <<< $'mput upload/*'
B15: =B$2&info!E10&B$3&CHAR(39)&B$4&CHAR(39) -> sftp -i p2pstorage.pem ec2-user@172.31.29.51:node <<< $'mput upload/*'
B16: =B$2&info!E11&B$3&CHAR(39)&B$4&CHAR(39) -> sftp -i p2pstorage.pem ec2-user@172.31.27.113:node <<< $'mput upload/*'
B17: =B$2&info!E12&B$3&CHAR(39)&B$4&CHAR(39) -> sftp -i p2pstorage.pem ec2-user@172.31.31.235:node <<< $'mput upload/*'
B18: =B$2&info!E13&B$3&CHAR(39)&B$4&CHAR(39) -> sftp -i p2pstorage.pem ec2-user@172.31.23.24:node <<< $'mput upload/*'
... B110: =B$2&info!E105&B$3&CHAR(39)&B$4&CHAR(39) -> sftp -i p2pstorage.pem ec2-user@172.31.28.55:node <<< $'mput upload/*'

Sheet downloadFiles
B2: sftp -i p2pstorage.pem ec2-user@ | H2: sftp -i p2pstorage.pem ec2-user@172.31.16.10:/home/ec2-user/node/logs/c01-t2-small_workload.csv
B3: :node/logs/
B4: _workload.csv
B7: =B$2&info!E2&B$3&info!D2&B$4 -> sftp -i p2pstorage.pem ec2-user@172.31.16.10:node/logs/c01-c5-4xlarge_workload.csv
B8: =B$2&info!E3&B$3&info!D3&B$4 -> sftp -i p2pstorage.pem ec2-user@172.31.27.28:node/logs/c02-t2-small_workload.csv
B9: =B$2&info!E4&B$3&info!D4&B$4 -> sftp -i p2pstorage.pem ec2-user@172.31.24.48:node/logs/c03-t2-small_workload.csv
B10: =B$2&info!E5&B$3&info!D5&B$4 -> sftp -i p2pstorage.pem ec2-user@172.31.19.20:node/logs/c04-t2-small_workload.csv
B11: =B$2&info!E6&B$3&info!D6&B$4 -> sftp -i p2pstorage.pem ec2-user@172.31.21.44:node/logs/c05-t2-medium_workload.csv
B12: =B$2&info!E7&B$3&info!D7&B$4 -> sftp -i p2pstorage.pem ec2-user@172.31.42.48:node/logs/c06-t2-medium_workload.csv
B13: =B$2&info!E8&B$3&info!D8&B$4 -> sftp -i p2pstorage.pem ec2-user@172.31.6.148:node/logs/c07-t2-medium_workload.csv
B14: =B$2&info!E9&B$3&info!D9&B$4 -> sftp -i p2pstorage.pem ec2-user@172.31.21.20:node/logs/c08-c5-xlarge_workload.csv
B15: =B$2&info!E10&B$3&info!D10&B$4 -> sftp -i p2pstorage.pem ec2-user@172.31.29.51:node/logs/c09-c5-xlarge_workload.csv
B16: =B$2&info!E11&B$3&info!D11&B$4 -> sftp -i p2pstorage.pem ec2-user@172.31.27.113:node/logs/c10-c5-2xlarge_workload.csv
B17: =B$2&info!E12&B$3&info!D12&B$4 -> sftp -i p2pstorage.pem ec2-user@172.31.31.235:node/logs/c11-c5-4xlarge_workload.csv
B18: =B$2&info!E13&B$3&info!D13&B$4 -> sftp -i p2pstorage.pem ec2-user@172.31.23.24:node/logs/c12-t2-small_workload.csv
... B110: =B$2&info!E105&B$3&info!D105&B$4 -> sftp -i p2pstorage.pem ec2-user@172.31.28.55:node/logs/c100-c5-2xlarge_workload.csv

Sheet info (BK)
B2: 01 | C2: t2-small | D2: ="c"&B2&"-"&C2 -> c01-t2-small | E2: 172.31.16.10 | F2: 0 0
B3: 02 | C3: t2-small | D3: ="c"&B3&"-"&C3 -> c02-t2-small | E3: 172.31.27.28 | F3: c01-t2-small 172.31.16.10
B4: 03 | C4: t2-medium | D4: ="c"&B4&"-"&C4 -> c03-t2-medium | E4: 172.31.24.48 | F4: c01-t2-small 172.31.16.10
A5: ` | B5: 04 | C5: t2-medium | D5: ="c"&B5&"-"&C5 -> c04-t2-medium | E5: 172.31.19.20 | F5: c01-t2-small 172.31.16.10
B6: 05 | C6: t2-large | D6: ="c"&B6&"-"&C6 -> c05-t2-large | E6: 172.31.21.44 | F6: c01-t2-small 172.31.16.10
B7: 06 | C7: t2-large | D7: ="c"&B7&"-"&C7 -> c06-t2-large | E7: 172.31.42.48 | F7: c01-t2-small 172.31.16.10
B8: 07 | C8: t3-small | D8: ="c"&B8&"-"&C8 -> c07-t3-small | E8: 172.31.6.148 | F8: c01-t2-small 172.31.16.10
B9: 08 | C9: t3-small | D9: ="c"&B9&"-"&C9 -> c08-t3-small | E9: 172.31.21.20 | F9: c01-t2-small 172.31.16.10
B10: 09 | C10: t3-medium | D10: ="c"&B10&"-"&C10 -> c09-t3-medium | E10: 172.31.29.51 | F10: c01-t2-small 172.31.16.10
B11: 10 | C11: t3-medium | D11: ="c"&B11&"-"&C11 -> c10-t3-medium | E11: 172.31.27.113 | F11: c01-t2-small 172.31.16.10
B12: 11 | C12: t2-small | D12: ="c"&B12&"-"&C12 -> c11-t2-small | E12: 172.31.31.235 | F12: c01-t2-small 172.31.16.10
B13: 12 | C13: t2-small | D13: ="c"&B13&"-"&C13 -> c12-t2-small | E13: 172.31.23.24 | F13: c01-t2-small 172.31.16.10
B14: 13 | C14: t2-medium | D14: ="c"&B14&"-"&C14 -> c13-t2-medium | E14: 172.31.28.220 | F14: c01-t2-small 172.31.16.10
B15: 14 | C15: t2-medium | D15: ="c"&B15&"-"&C15 -> c14-t2-medium | E15: 172.31.28.38 | F15: c01-t2-small 172.31.16.10
B16: 15 | C16: t2-large | D16: ="c"&B16&"-"&C16 -> c15-t2-large | E16: 172.31.31.7 | F16: c01-t2-small 172.31.16.10
B17: 16 | C17: t2-large | D17: ="c"&B17&"-"&C17 -> c16-t2-large | E17: 172.31.19.38 | F17: c01-t2-small 172.31.16.10
B18: 17 | C18: t3-small | D18: ="c"&B18&"-"&C18 -> c17-t3-small | E18: 172.31.19.160 | F18: c01-t2-small 172.31.16.10
B19: 18 | C19: t3-small | D19: ="c"&B19&"-"&C19 -> c18-t3-small | E19: 172.31.16.91 | F19: c01-t2-small 172.31.16.10
B20: 19 | C20: t3-medium | D20: ="c"&B20&"-"&C20 -> c19-t3-medium | E20: 172.31.22.207 | F20: c01-t2-small 172.31.16.10
B21: 20 | C21: t3-medium | D21: ="c"&B21&"-"&C21 -> c20-t3-medium | E21: 172.31.25.39 | F21: c01-t2-small 172.31.16.10
B23: 21 | C23: t2-small | D23: ="c"&B23&"-"&C23 -> c21-t2-small | E23: 172.31.18.213 | F23: c01-t2-small 172.31.16.10
... B105: 100 | C105: t3-medium | D105: ="c"&B105&"-"&C105 -> c100-t3-medium | E105: 172.31.28.55 | F105: c85-t2-large 172.31.23.251
